Workbook
Name DatosExternos_1: IndicadoresPIIP!#REF!
Name PERIODO: Parametros!$A$2:$A$4

Sheet CriteriosCruce
A1: Definicion de acto_admon y objeto_reg en compromisos
A2: acto_admon → a través de qué modalidad se comprometen los recursos (contrato, resolución, orden de pago…).
A3: OBJETO_REG → con qué objeto / para qué se comprometen.
A5: Diferencias entre acto_admon (en compromisos) y tipo orden de gasto (en obligaciones)
A6: La única diferencia: el acto_admon trae el número del acto específico (…SALUD 285), y el tipo_orden_gasto es la categoría limpia, sin número (…SALUD).
A7: Es la misma modalidad, en dos momentos:
A8: acto_admon → en el compromiso (RP), texto libre con el número del acto. Sirve para trazar al documento exacto.
A9: tipo_orden_gasto → en la obligación, ya normalizado en catálogo (la dimensión OrdenGasto), sin número. Sirve para agrupar/clasificar.
A10: Piénsalo así: el tipo_orden_gasto es el acto_admon sin el número — SIIFWEB lo estandariza en una categoría cuando llegas a la obligación
A12: relacion entre historico_orden_orden_gasto_2 y orden de gasto por fecha
A13: Llave del contrato: tipo_contrato + nro_contrato + fecha_firma + NIT
A14: Identifican un contrato de forma única — verificado sobre el histórico: 9.789 grupos = 9.789 contratos reales, 0 colisiones de duración. Cada campo aporta:
... A19: Por qué se incluye el tipo (caso real): el contrato N.º 12 de M3 Soluciones Integrales SAS, firmado el 2023-11-03 (objeto: apoyo logístico), aparece con el mismo número, fecha y NIT pero dos tipos distintos — CONTRATO ADICIONAL LP ($90.000.000) y CONTRATO ADICIONAL MENOR CUANTIA ($320.000.000). Son dos adiciones al mismo contrato registradas con modalidad diferente. Sin el tipo, se fusionarían en un solo registro y perderías una. Es el único caso en ~9.800, pero justifica dejar el tipo en la llave.

Sheet Notas
A1: PASOS PARA CONSOLIDACIÓN
A2: PASO | B2: DESCRIPCION | C2: NOTA
A3: 1 | B3: Descargar reporte de cuipo de ejecución de gastos de datos abiertos: https://www.datos.gov.co/Gastos-Gubernamentales/OVCF-CUIPO-Ejecuci-n-de-Gastos/4f7r-epif/about_data | C3: Se excluyen reservas (obligaciones realizadas en una vigencia posterior)
A4: 2 | B4: Descargar reporte de ejecución acumulada de productos PIIP | C4: Se recomienda descargar de forma mensual porque PIIP no genera un reporte de ejecución trimestral. Toca tomar el reporte del ultimo mes del trimestre para tener el dato acumulado hasta ese corte
A5: 3 | B5: En el archivo Carga masiva IP - 70 - 20260805 las columnas de totales de presupuesto ordinario deben de modificarse para que no incluyan la formula. Power query no las lee cuando la columna tiene referencia a una formula
A7: Calculo
A8: 1 | B8: El cruce entre sispt, piip y cuipo se hace a traves del codigo de producto
A9: 2 | B9: Ellos realizan una agrupación a nivel de producto agregando mediante suma la programación fisica de la vigencia que vayan a evaluar. De esa forma, si un plan tiene un indicador duplicado, la agrupación asegura un unico producto con una unica programación en el plan
A10: 3 | B10: Para la ejecución física, se agrupan los productos de los proyectos que hayan registrado ejecución en el periodo y se agregan mediante suma.
A11: 4 | B11: Para la ejecución financiera, se agrupan los productos de los proyectos que hayan registrado obligaciones en el periodo (excluyendo reservas) y se agregan mediante suma.
A12: 5 | B12: Solo se considaran para el calculo los productos del índice de Eficacia base que tengan programación fisica, ejecución fisica y obligaciones en la vigencia. El resto se excluye

Sheet Reporte
A1: PERIODO | B1: 20260601 | C1: COMPROMISOS PERIODO | D1: =SUMIFS(CUIPO_datos_abiertos[COMPROMISOS],CUIPO_datos_abiertos[ES_PRODUCTO_VALIDO],"VALIDO",CUIPO_datos_abiertos[PERIODO],'Reporte'!$B$1) -> 641956722135 | E1: EFICACIA | F1: {=SUM(_xlfn._xlws.FILTER(Reporte[Aporte],Reporte[Aporte]<>""))} -> 0.023014005
A3: ="INDICE DE EFICACIA BASE " & INDEX(TablaPeriodos[],MATCH('Reporte'!$B$1,TablaPeriodos[Periodo],0),3) -> INDICE DE EFICACIA BASE SEGUNDO TRIMESTRE 2026
A5: Cód. Prod. | B5: Producto | C5: Cód. Ind. | D5: Indicador | E5: Programación Física de la Meta | F5: Ejecución Física PIIP | G5: Eje. Fís. SISPT | H5: Ver. Eje. Fís | I5: Proyectos Reporte PIIP | J5: Compromisos (CUIPO) | K5: Obligaciones (CUIPO) | L5: ¿Se tiene en cuenta para el calculo? | M5: Avance físico (%) | N5: Avance ajustado (%) | O5: Ponderador (wi) | P5: Aporte
A6: 2201071 | B6: Servicio educativo | C6: 220107100 | D6: Establecimientos educativos en operación | E6: {=_xlfn._xlws.FILTER(PI_SISPT_ProgramacionFisica[Prog. Fís.],(PI_SISPT_ProgramacionFisica[Cód. Prod.]=Reporte[[#This Row],[Cód. Prod.]])*(PI_SISPT_ProgramacionFisica[Vigencia]=LEFT('Reporte'!$B$1,4)))} -> 265 | F6: =SUMIFS(EjecucionPIIP[AvanceEjecutado],EjecucionPIIP[CodigoProducto],Reporte[[#This Row],[Cód. Prod.]],EjecucionPIIP[Periodo],$B$1,EjecucionPIIP[AvanceEjecutado],"<>0") -> 0 | G6: {=_xlfn._xlws.FILTER(ReporteEficacia[Meta ejecutada],(ReporteEficacia[Código producto]=Reporte[[#This Row],[Cód. Prod.]])*(ReporteEficacia[Periodo]='Reporte'!$B$1))} -> #VALUE! | H6: =IF(Reporte[[#This Row],[Ejecución Física PIIP]]=Reporte[[#This Row],[Eje. Fís. SISPT]],"Coincide","No coincide") -> #VALUE! | I6: {=_xlfn.TEXTJOIN(", ",TRUE,_xlfn._xlws.FILTER(EjecucionPIIP[Bpin],(EjecucionPIIP[Periodo]='Reporte'!$B$1)*(EjecucionPIIP[CodigoProducto]=Reporte[[#This Row],[Cód. Prod.]]),""))} -> 202500000049907 | J6: =SUMIFS(CUIPO_datos_abiertos[COMPROMISOS],CUIPO_datos_abiertos[COD_PROGRAMATICO_MGA],Reporte[[#This Row],[Cód. Prod.]],CUIPO_datos_abiertos[PERIODO],$B$1) -> 393505224553 | K6: =SUMIFS(CUIPO_datos_abiertos[OBLIGACIONES],CUIPO_datos_abiertos[COD_PROGRAMATICO_MGA],Reporte[[#This Row],[Cód. Prod.]],CUIPO_datos_abiertos[PERIODO],$B$1) -> 367702338497 | L6: =IF(AND(Reporte[[#This Row],[Programación Física de la Meta]]=0,Reporte[[#This Row],[Ejecución Física PIIP]]<>0,Reporte[[#This Row],[Obligaciones (CUIPO)]]<>0),"Excluidos",IF(AND(Reporte[[#This Row],[Programación Física de la Meta]]<>0,Reporte[[#This Row],[Ejecución Física PIIP]]<>0,Reporte[[#This Row],[Obligaciones (CUIPO)]]<>0),"Aporta al calculo","")) | M6: =IF(Reporte[[#This Row],[¿Se tiene en cuenta para el calculo?]]="Aporta al calculo",Reporte[[#This Row],[Ejecución Física PIIP]]/Reporte[[#This Row],[Programación Física de la Meta]],"") | N6: =IF(Reporte[[#This Row],[¿Se tiene en cuenta para el calculo?]]="Aporta al calculo",IF(Reporte[[#This Row],[Avance físico (%)]]>1,1,Reporte[[#This Row],[Avance físico (%)]]),"") | O6: =IF(Reporte[[#This Row],[¿Se tiene en cuenta para el calculo?]]="Aporta al calculo",Reporte[[#This Row],[Obligaciones (CUIPO)]]/$D$1,"") | P6: =IF(Reporte[[#This Row],[¿Se tiene en cuenta para el calculo?]]="Aporta al calculo",Reporte[[#This Row],[Avance ajustado (%)]]*Reporte[[#This Row],[Ponderador (wi)]],"")
A7: 2402018 | B7: Vía secundaria rehabilitada | C7: 240201800 | D7: Vía secundaria rehabilitada | E7: {=_xlfn._xlws.FILTER(PI_SISPT_ProgramacionFisica[Prog. Fís.],(PI_SISPT_ProgramacionFisica[Cód. Prod.]=Reporte[[#This Row],[Cód. Prod.]])*(PI_SISPT_ProgramacionFisica[Vigencia]=LEFT('Reporte'!$B$1,4)))} -> 8.7 | F7: =SUMIFS(EjecucionPIIP[AvanceEjecutado],EjecucionPIIP[CodigoProducto],Reporte[[#This Row],[Cód. Prod.]],EjecucionPIIP[Periodo],$B$1,EjecucionPIIP[AvanceEjecutado],"<>0") -> 0 | G7: {=_xlfn._xlws.FILTER(ReporteEficacia[Meta ejecutada],(ReporteEficacia[Código producto]=Reporte[[#This Row],[Cód. Prod.]])*(ReporteEficacia[Periodo]='Reporte'!$B$1))} -> #VALUE! | H7: =IF(Reporte[[#This Row],[Ejecución Física PIIP]]=Reporte[[#This Row],[Eje. Fís. SISPT]],"Coincide","No coincide") -> #VALUE! | I7: {=_xlfn.TEXTJOIN(", ",TRUE,_xlfn._xlws.FILTER(EjecucionPIIP[Bpin],(EjecucionPIIP[Periodo]='Reporte'!$B$1)*(EjecucionPIIP[CodigoProducto]=Reporte[[#This Row],[Cód. Prod.]]),""))} | J7: =SUMIFS(CUIPO_datos_abiertos[COMPROMISOS],CUIPO_datos_abiertos[COD_PROGRAMATICO_MGA],Reporte[[#This Row],[Cód. Prod.]],CUIPO_datos_abiertos[PERIODO],$B$1) -> 33431816466 | K7: =SUMIFS(CUIPO_datos_abiertos[OBLIGACIONES],CUIPO_datos_abiertos[COD_PROGRAMATICO_MGA],Reporte[[#This Row],[Cód. Prod.]],CUIPO_datos_abiertos[PERIODO],$B$1) -> 15280589499 | L7: =IF(AND(Reporte[[#This Row],[Programación Física de la Meta]]=0,Reporte[[#This Row],[Ejecución Física PIIP]]<>0,Reporte[[#This Row],[Obligaciones (CUIPO)]]<>0),"Excluidos",IF(AND(Reporte[[#This Row],[Programación Física de la Meta]]<>0,Reporte[[#This Row],[Ejecución Física PIIP]]<>0,Reporte[[#This Row],[Obligaciones (CUIPO)]]<>0),"Aporta al calculo","")) | M7: =IF(Reporte[[#This Row],[¿Se tiene en cuenta para el calculo?]]="Aporta al calculo",Reporte[[#This Row],[Ejecución Física PIIP]]/Reporte[[#This Row],[Programación Física de la Meta]],"") | N7: =IF(Reporte[[#This Row],[¿Se tiene en cuenta para el calculo?]]="Aporta al calculo",IF(Reporte[[#This Row],[Avance físico (%)]]>1,1,Reporte[[#This Row],[Avance físico (%)]]),"") | O7: =IF(Reporte[[#This Row],[¿Se tiene en cuenta para el calculo?]]="Aporta al calculo",Reporte[[#This Row],[Obligaciones (CUIPO)]]/$D$1,"") | P7: =IF(Reporte[[#This Row],[¿Se tiene en cuenta para el calculo?]]="Aporta al calculo",Reporte[[#This Row],[Avance ajustado (%)]]*Reporte[[#This Row],[Ponderador (wi)]],"")
A8: 4599003 | B8: Servicio de reeestructuracion de pasivos | C8: 459900300 | D8: Acuerdo de reestructuración de pasivos ejecutado | E8: {=_xlfn._xlws.FILTER(PI_SISPT_ProgramacionFisica[Prog. Fís.],(PI_SISPT_ProgramacionFisica[Cód. Prod.]=Reporte[[#This Row],[Cód. Prod.]])*(PI_SISPT_ProgramacionFisica[Vigencia]=LEFT('Reporte'!$B$1,4)))} -> 0.13 | F8: =SUMIFS(EjecucionPIIP[AvanceEjecutado],EjecucionPIIP[CodigoProducto],Reporte[[#This Row],[Cód. Prod.]],EjecucionPIIP[Periodo],$B$1,EjecucionPIIP[AvanceEjecutado],"<>0") -> 0 | G8: {=_xlfn._xlws.FILTER(ReporteEficacia[Meta ejecutada],(ReporteEficacia[Código producto]=Reporte[[#This Row],[Cód. Prod.]])*(ReporteEficacia[Periodo]='Reporte'!$B$1))} -> #VALUE! | H8: =IF(Reporte[[#This Row],[Ejecución Física PIIP]]=Reporte[[#This Row],[Eje. Fís. SISPT]],"Coincide","No coincide") -> #VALUE! | I8: {=_xlfn.TEXTJOIN(", ",TRUE,_xlfn._xlws.FILTER(EjecucionPIIP[Bpin],(EjecucionPIIP[Periodo]='Reporte'!$B$1)*(EjecucionPIIP[CodigoProducto]=Reporte[[#This Row],[Cód. Prod.]]),""))} | J8: =SUMIFS(CUIPO_datos_abiertos[COMPROMISOS],CUIPO_datos_abiertos[COD_PROGRAMATICO_MGA],Reporte[[#This Row],[Cód. Prod.]],CUIPO_datos_abiertos[PERIODO],$B$1) -> 12909544680 | K8: =SUMIFS(CUIPO_datos_abiertos[OBLIGACIONES],CUIPO_datos_abiertos[COD_PROGRAMATICO_MGA],Reporte[[#This Row],[Cód. Prod.]],CUIPO_datos_abiertos[PERIODO],$B$1) -> 12532668173 | L8: =IF(AND(Reporte[[#This Row],[Programación Física de la Meta]]=0,Reporte[[#This Row],[Ejecución Física PIIP]]<>0,Reporte[[#This Row],[Obligaciones (CUIPO)]]<>0),"Excluidos",IF(AND(Reporte[[#This Row],[Programación Física de la Meta]]<>0,Reporte[[#This Row],[Ejecución Física PIIP]]<>0,Reporte[[#This Row],[Obligaciones (CUIPO)]]<>0),"Aporta al calculo","")) | M8: =IF(Reporte[[#This Row],[¿Se tiene en cuenta para el calculo?]]="Aporta al calculo",Reporte[[#This Row],[Ejecución Física PIIP]]/Reporte[[#This Row],[Programación Física de la Meta]],"") | N8: =IF(Reporte[[#This Row],[¿Se tiene en cuenta para el calculo?]]="Aporta al calculo",IF(Reporte[[#This Row],[Avance físico (%)]]>1,1,Reporte[[#This Row],[Avance físico (%)]]),"") | O8: =IF(Reporte[[#This Row],[¿Se tiene en cuenta para el calculo?]]="Aporta al calculo",Reporte[[#This Row],[Obligaciones (CUIPO)]]/$D$1,"") | P8: =IF(Reporte[[#This Row],[¿Se tiene en cuenta para el calculo?]]="Aporta al calculo",Reporte[[#This Row],[Avance ajustado (%)]]*Reporte[[#This Row],[Ponderador (wi)]],"")
A9: 2201028 | B9: Servicio de apoyo a la permanencia con alimentación escolar | C9: 220102800 | D9: Raciones contratadas | E9: {=_xlfn._xlws.FILTER(PI_SISPT_ProgramacionFisica[Prog. Fís.],(PI_SISPT_ProgramacionFisica[Cód. Prod.]=Reporte[[#This Row],[Cód. Prod.]])*(PI_SISPT_ProgramacionFisica[Vigencia]=LEFT('Reporte'!$B$1,4)))} -> 8000000 | F9: =SUMIFS(EjecucionPIIP[AvanceEjecutado],EjecucionPIIP[CodigoProducto],Reporte[[#This Row],[Cód. Prod.]],EjecucionPIIP[Periodo],$B$1,EjecucionPIIP[AvanceEjecutado],"<>0") -> 1740449 | G9: {=_xlfn._xlws.FILTER(ReporteEficacia[Meta ejecutada],(ReporteEficacia[Código producto]=Reporte[[#This Row],[Cód. Prod.]])*(ReporteEficacia[Periodo]='Reporte'!$B$1))} -> #VALUE! | H9: =IF(Reporte[[#This Row],[Ejecución Física PIIP]]=Reporte[[#This Row],[Eje. Fís. SISPT]],"Coincide","No coincide") -> #VALUE! | I9: {=_xlfn.TEXTJOIN(", ",TRUE,_xlfn._xlws.FILTER(EjecucionPIIP[Bpin],(EjecucionPIIP[Periodo]='Reporte'!$B$1)*(EjecucionPIIP[CodigoProducto]=Reporte[[#This Row],[Cód. Prod.]]),""))} -> 202500000035386, 202500000042419 | J9: =SUMIFS(CUIPO_datos_abiertos[COMPROMISOS],CUIPO_datos_abiertos[COD_PROGRAMATICO_MGA],Reporte[[#This Row],[Cód. Prod.]],CUIPO_datos_abiertos[PERIODO],$B$1) -> 29734014223 | K9: =SUMIFS(CUIPO_datos_abiertos[OBLIGACIONES],CUIPO_datos_abiertos[COD_PROGRAMATICO_MGA],Reporte[[#This Row],[Cód. Prod.]],CUIPO_datos_abiertos[PERIODO],$B$1) -> 12363581024 | L9: =IF(AND(Reporte[[#This Row],[Programación Física de la Meta]]=0,Reporte[[#This Row],[Ejecución Física PIIP]]<>0,Reporte[[#This Row],[Obligaciones (CUIPO)]]<>0),"Excluidos",IF(AND(Reporte[[#This Row],[Programación Física de la Meta]]<>0,Reporte[[#This Row],[Ejecución Física PIIP]]<>0,Reporte[[#This Row],[Obligaciones (CUIPO)]]<>0),"Aporta al calculo","")) -> Aporta al calculo | M9: =IF(Reporte[[#This Row],[¿Se tiene en cuenta para el calculo?]]="Aporta al calculo",Reporte[[#This Row],[Ejecución Física PIIP]]/Reporte[[#This Row],[Programación Física de la Meta]],"") -> 0.21755612 | N9: =IF(Reporte[[#This Row],[¿Se tiene en cuenta para el calculo?]]="Aporta al calculo",IF(Reporte[[#This Row],[Avance físico (%)]]>1,1,Reporte[[#This Row],[Avance físico (%)]]),"") -> 0.21755612 | O9: =IF(Reporte[[#This Row],[¿Se tiene en cuenta para el calculo?]]="Aporta al calculo",Reporte[[#This Row],[Obligaciones (CUIPO)]]/$D$1,"") -> 0.019259213 | P9: =IF(Reporte[[#This Row],[¿Se tiene en cuenta para el calculo?]]="Aporta al calculo",Reporte[[#This Row],[Avance ajustado (%)]]*Reporte[[#This Row],[Ponderador (wi)]],"") -> 0.0041899597
A10: 1906030 | B10: Hospitales de primer nivel de atención construidos y dotados | C10: 190603000 | D10: Hospitales de primer nivel de atención construidos y dotados | E10: {=_xlfn._xlws.FILTER(PI_SISPT_ProgramacionFisica[Prog. Fís.],(PI_SISPT_ProgramacionFisica[Cód. Prod.]=Reporte[[#This Row],[Cód. Prod.]])*(PI_SISPT_ProgramacionFisica[Vigencia]=LEFT('Reporte'!$B$1,4)))} -> 0 | F10: =SUMIFS(EjecucionPIIP[AvanceEjecutado],EjecucionPIIP[CodigoProducto],Reporte[[#This Row],[Cód. Prod.]],EjecucionPIIP[Periodo],$B$1,EjecucionPIIP[AvanceEjecutado],"<>0") -> 0 | G10: {=_xlfn._xlws.FILTER(ReporteEficacia[Meta ejecutada],(ReporteEficacia[Código producto]=Reporte[[#This Row],[Cód. Prod.]])*(ReporteEficacia[Periodo]='Reporte'!$B$1))} -> #VALUE! | H10: =IF(Reporte[[#This Row],[Ejecución Física PIIP]]=Reporte[[#This Row],[Eje. Fís. SISPT]],"Coincide","No coincide") -> #VALUE! | I10: {=_xlfn.TEXTJOIN(", ",TRUE,_xlfn._xlws.FILTER(EjecucionPIIP[Bpin],(EjecucionPIIP[Periodo]='Reporte'!$B$1)*(EjecucionPIIP[CodigoProducto]=Reporte[[#This Row],[Cód. Prod.]]),""))} -> 2023002700021 | J10: =SUMIFS(CUIPO_datos_abiertos[COMPROMISOS],CUIPO_datos_abiertos[COD_PROGRAMATICO_MGA],Reporte[[#This Row],[Cód. Prod.]],CUIPO_datos_abiertos[PERIODO],$B$1) -> 22295459973 | K10: =SUMIFS(CUIPO_datos_abiertos[OBLIGACIONES],CUIPO_datos_abiertos[COD_PROGRAMATICO_MGA],Reporte[[#This Row],[Cód. Prod.]],CUIPO_datos_abiertos[PERIODO],$B$1) -> 9991793731 | L10: =IF(AND(Reporte[[#This Row],[Programación Física de la Meta]]=0,Reporte[[#This Row],[Ejecución Física PIIP]]<>0,Reporte[[#This Row],[Obligaciones (CUIPO)]]<>0),"Excluidos",IF(AND(Reporte[[#This Row],[Programación Física de la Meta]]<>0,Reporte[[#This Row],[Ejecución Física PIIP]]<>0,Reporte[[#This Row],[Obligaciones (CUIPO)]]<>0),"Aporta al calculo","")) | M10: =IF(Reporte[[#This Row],[¿Se tiene en cuenta para el calculo?]]="Aporta al calculo",Reporte[[#This Row],[Ejecución Física PIIP]]/Reporte[[#This Row],[Programación Física de la Meta]],"") | N10: =IF(Reporte[[#This Row],[¿Se tiene en cuenta para el calculo?]]="Aporta al calculo",IF(Reporte[[#This Row],[Avance físico (%)]]>1,1,Reporte[[#This Row],[Avance físico (%)]]),"") | O10: =IF(Reporte[[#This Row],[¿Se tiene en cuenta para el calculo?]]="Aporta al calculo",Reporte[[#This Row],[Obligaciones (CUIPO)]]/$D$1,"") | P10: =IF(Reporte[[#This Row],[¿Se tiene en cuenta para el calculo?]]="Aporta al calculo",Reporte[[#This Row],[Avance ajustado (%)]]*Reporte[[#This Row],[Ponderador (wi)]],"")
A11: 4501079 | B11: Servicio de dotación para la movilidad operacional y el apoyo logístico | C11: 450107900 | D11: Unidades dotadas | E11: {=_xlfn._xlws.FILTER(PI_SISPT_ProgramacionFisica[Prog. Fís.],(PI_SISPT_ProgramacionFisica[Cód. Prod.]=Reporte[[#This Row],[Cód. Prod.]])*(PI_SISPT_ProgramacionFisica[Vigencia]=LEFT('Reporte'!$B$1,4)))} -> 9 | F11: =SUMIFS(EjecucionPIIP[AvanceEjecutado],EjecucionPIIP[CodigoProducto],Reporte[[#This Row],[Cód. Prod.]],EjecucionPIIP[Periodo],$B$1,EjecucionPIIP[AvanceEjecutado],"<>0") -> 0 | G11: {=_xlfn._xlws.FILTER(ReporteEficacia[Meta ejecutada],(ReporteEficacia[Código producto]=Reporte[[#This Row],[Cód. Prod.]])*(ReporteEficacia[Periodo]='Reporte'!$B$1))} -> #VALUE! | H11: =IF(Reporte[[#This Row],[Ejecución Física PIIP]]=Reporte[[#This Row],[Eje. Fís. SISPT]],"Coincide","No coincide") -> #VALUE! | I11: {=_xlfn.TEXTJOIN(", ",TRUE,_xlfn._xlws.FILTER(EjecucionPIIP[Bpin],(EjecucionPIIP[Periodo]='Reporte'!$B$1)*(EjecucionPIIP[CodigoProducto]=Reporte[[#This Row],[Cód. Prod.]]),""))} | J11: =SUMIFS(CUIPO_datos_abiertos[COMPROMISOS],CUIPO_datos_abiertos[COD_PROGRAMATICO_MGA],Reporte[[#This Row],[Cód. Prod.]],CUIPO_datos_abiertos[PERIODO],$B$1) -> 7718197813 | K11: =SUMIFS(CUIPO_datos_abiertos[OBLIGACIONES],CUIPO_datos_abiertos[COD_PROGRAMATICO_MGA],Reporte[[#This Row],[Cód. Prod.]],CUIPO_datos_abiertos[PERIODO],$B$1) -> 7718197813 | L11: =IF(AND(Reporte[[#This Row],[Programación Física de la Meta]]=0,Reporte[[#This Row],[Ejecución Física PIIP]]<>0,Reporte[[#This Row],[Obligaciones (CUIPO)]]<>0),"Excluidos",IF(AND(Reporte[[#This Row],[Programación Física de la Meta]]<>0,Reporte[[#This Row],[Ejecución Física PIIP]]<>0,Reporte[[#This Row],[Obligaciones (CUIPO)]]<>0),"Aporta al calculo","")) | M11: =IF(Reporte[[#This Row],[¿Se tiene en cuenta para el calculo?]]="Aporta al calculo",Reporte[[#This Row],[Ejecución Física PIIP]]/Reporte[[#This Row],[Programación Física de la Meta]],"") | N11: =IF(Reporte[[#This Row],[¿Se tiene en cuenta para el calculo?]]="Aporta al calculo",IF(Reporte[[#This Row],[Avance físico (%)]]>1,1,Reporte[[#This Row],[Avance físico (%)]]),"") | O11: =IF(Reporte[[#This Row],[¿Se tiene en cuenta para el calculo?]]="Aporta al calculo",Reporte[[#This Row],[Obligaciones (CUIPO)]]/$D$1,"") | P11: =IF(Reporte[[#This Row],[¿Se tiene en cuenta para el calculo?]]="Aporta al calculo",Reporte[[#This Row],[Avance ajustado (%)]]*Reporte[[#This Row],[Ponderador (wi)]],"")
A12: 4599031 | B12: Servicio de asistencia técnica | C12: 459903100 | D12: Entidades, organismos y dependencias asistidos técnicamente | E12: {=_xlfn._xlws.FILTER(PI_SISPT_ProgramacionFisica[Prog. Fís.],(PI_SISPT_ProgramacionFisica[Cód. Prod.]=Reporte[[#This Row],[Cód. Prod.]])*(PI_SISPT_ProgramacionFisica[Vigencia]=LEFT('Reporte'!$B$1,4)))} -> 14 | F12: =SUMIFS(EjecucionPIIP[AvanceEjecutado],EjecucionPIIP[CodigoProducto],Reporte[[#This Row],[Cód. Prod.]],EjecucionPIIP[Periodo],$B$1,EjecucionPIIP[AvanceEjecutado],"<>0") -> 1 | G12: {=_xlfn._xlws.FILTER(ReporteEficacia[Meta ejecutada],(ReporteEficacia[Código producto]=Reporte[[#This Row],[Cód. Prod.]])*(ReporteEficacia[Periodo]='Reporte'!$B$1))} -> #VALUE! | H12: =IF(Reporte[[#This Row],[Ejecución Física PIIP]]=Reporte[[#This Row],[Eje. Fís. SISPT]],"Coincide","No coincide") -> #VALUE! | I12: {=_xlfn.TEXTJOIN(", ",TRUE,_xlfn._xlws.FILTER(EjecucionPIIP[Bpin],(EjecucionPIIP[Periodo]='Reporte'!$B$1)*(EjecucionPIIP[CodigoProducto]=Reporte[[#This Row],[Cód. Prod.]]),""))} -> 202500000025321, 202500000050078, 202600000005933 | J12: =SUMIFS(CUIPO_datos_abiertos[COMPROMISOS],CUIPO_datos_abiertos[COD_PROGRAMATICO_MGA],Reporte[[#This Row],[Cód. Prod.]],CUIPO_datos_abiertos[PERIODO],$B$1) -> 6527729587 | K12: =SUMIFS(CUIPO_datos_abiertos[OBLIGACIONES],CUIPO_datos_abiertos[COD_PROGRAMATICO_MGA],Reporte[[#This Row],[Cód. Prod.]],CUIPO_datos_abiertos[PERIODO],$B$1) -> 5864726020 | L12: =IF(AND(Reporte[[#This Row],[Programación Física de la Meta]]=0,Reporte[[#This Row],[Ejecución Física PIIP]]<>0,Reporte[[#This Row],[Obligaciones (CUIPO)]]<>0),"Excluidos",IF(AND(Reporte[[#This Row],[Programación Física de la Meta]]<>0,Reporte[[#This Row],[Ejecución Física PIIP]]<>0,Reporte[[#This Row],[Obligaciones (CUIPO)]]<>0),"Aporta al calculo","")) -> Aporta al calculo | M12: =IF(Reporte[[#This Row],[¿Se tiene en cuenta para el calculo?]]="Aporta al calculo",Reporte[[#This Row],[Ejecución Física PIIP]]/Reporte[[#This Row],[Programación Física de la Meta]],"") -> 0.071428571 | N12: =IF(Reporte[[#This Row],[¿Se tiene en cuenta para el calculo?]]="Aporta al calculo",IF(Reporte[[#This Row],[Avance físico (%)]]>1,1,Reporte[[#This Row],[Avance físico (%)]]),"") -> 0.071428571 | O12: =IF(Reporte[[#This Row],[¿Se tiene en cuenta para el calculo?]]="Aporta al calculo",Reporte[[#This Row],[Obligaciones (CUIPO)]]/$D$1,"") -> 0.0091357031 | P12: =IF(Reporte[[#This Row],[¿Se tiene en cuenta para el calculo?]]="Aporta al calculo",Reporte[[#This Row],[Avance ajustado (%)]]*Reporte[[#This Row],[Ponderador (wi)]],"") -> 0.00065255022
A13: 1903035 | B13: Servicio de inspección, vigilancia y control de los factores del riesgo del ambiente que afectan la salud humana | C13: 190303500 | D13: Distritos con acciones de Inspección Vigilancia y Control reales y efectivas de los factores del riesgo del ambiente que afectan la salud humana realizados | E13: {=_xlfn._xlws.FILTER(PI_SISPT_ProgramacionFisica[Prog. Fís.],(PI_SISPT_ProgramacionFisica[Cód. Prod.]=Reporte[[#This Row],[Cód. Prod.]])*(PI_SISPT_ProgramacionFisica[Vigencia]=LEFT('Reporte'!$B$1,4)))} -> 3 | F13: =SUMIFS(EjecucionPIIP[AvanceEjecutado],EjecucionPIIP[CodigoProducto],Reporte[[#This Row],[Cód. Prod.]],EjecucionPIIP[Periodo],$B$1,EjecucionPIIP[AvanceEjecutado],"<>0") -> 0.5 | G13: {=_xlfn._xlws.FILTER(ReporteEficacia[Meta ejecutada],(ReporteEficacia[Código producto]=Reporte[[#This Row],[Cód. Prod.]])*(ReporteEficacia[Periodo]='Reporte'!$B$1))} -> #VALUE! | H13: =IF(Reporte[[#This Row],[Ejecución Física PIIP]]=Reporte[[#This Row],[Eje. Fís. SISPT]],"Coincide","No coincide") -> #VALUE! | I13: {=_xlfn.TEXTJOIN(", ",TRUE,_xlfn._xlws.FILTER(EjecucionPIIP[Bpin],(EjecucionPIIP[Periodo]='Reporte'!$B$1)*(EjecucionPIIP[CodigoProducto]=Reporte[[#This Row],[Cód. Prod.]]),""))} -> 202500000047955 | J13: =SUMIFS(CUIPO_datos_abiertos[COMPROMISOS],CUIPO_datos_abiertos[COD_PROGRAMATICO_MGA],Reporte[[#This Row],[Cód. Prod.]],CUIPO_datos_abiertos[PERIODO],$B$1) -> 7164506229 | K13: =SUMIFS(CUIPO_datos_abiertos[OBLIGACIONES],CUIPO_datos_abiertos[COD_PROGRAMATICO_MGA],Reporte[[#This Row],[Cód. Prod.]],CUIPO_datos_abiertos[PERIODO],$B$1) -> 4450475298 | L13: =IF(AND(Reporte[[#This Row],[Programación Física de la Meta]]=0,Reporte[[#This Row],[Ejecución Física PIIP]]<>0,Reporte[[#This Row],[Obligaciones (CUIPO)]]<>0),"Excluidos",IF(AND(Reporte[[#This Row],[Programación Física de la Meta]]<>0,Reporte[[#This Row],[Ejecución Física PIIP]]<>0,Reporte[[#This Row],[Obligaciones (CUIPO)]]<>0),"Aporta al calculo","")) -> Aporta al calculo | M13: =IF(Reporte[[#This Row],[¿Se tiene en cuenta para el calculo?]]="Aporta al calculo",Reporte[[#This Row],[Ejecución Física PIIP]]/Reporte[[#This Row],[Programación Física de la Meta]],"") -> 0.16666667 | N13: =IF(Reporte[[#This Row],[¿Se tiene en cuenta para el calculo?]]="Aporta al calculo",IF(Reporte[[#This Row],[Avance físico (%)]]>1,1,Reporte[[#This Row],[Avance físico (%)]]),"") -> 0.16666667 | O13: =IF(Reporte[[#This Row],[¿Se tiene en cuenta para el calculo?]]="Aporta al calculo",Reporte[[#This Row],[Obligaciones (CUIPO)]]/$D$1,"") -> 0.0069326719 | P13: =IF(Reporte[[#This Row],[¿Se tiene en cuenta para el calculo?]]="Aporta al calculo",Reporte[[#This Row],[Avance ajustado (%)]]*Reporte[[#This Row],[Ponderador (wi)]],"") -> 0.0011554453
A14: 4301001 | B14: Servicio de apoyo a la actividad física, la recreación y el deporte | C14: 430100100 | D14: Personas beneficiadas | E14: {=_xlfn._xlws.FILTER(PI_SISPT_ProgramacionFisica[Prog. Fís.],(PI_SISPT_ProgramacionFisica[Cód. Prod.]=Reporte[[#This Row],[Cód. Prod.]])*(PI_SISPT_ProgramacionFisica[Vigencia]=LEFT('Reporte'!$B$1,4)))} -> 17500 | F14: =SUMIFS(EjecucionPIIP[AvanceEjecutado],EjecucionPIIP[CodigoProducto],Reporte[[#This Row],[Cód. Prod.]],EjecucionPIIP[Periodo],$B$1,EjecucionPIIP[AvanceEjecutado],"<>0") -> 953324 | G14: {=_xlfn._xlws.FILTER(ReporteEficacia[Meta ejecutada],(ReporteEficacia[Código producto]=Reporte[[#This Row],[Cód. Prod.]])*(ReporteEficacia[Periodo]='Reporte'!$B$1))} -> #VALUE! | H14: =IF(Reporte[[#This Row],[Ejecución Física PIIP]]=Reporte[[#This Row],[Eje. Fís. SISPT]],"Coincide","No coincide") -> #VALUE! | I14: {=_xlfn.TEXTJOIN(", ",TRUE,_xlfn._xlws.FILTER(EjecucionPIIP[Bpin],(EjecucionPIIP[Periodo]='Reporte'!$B$1)*(EjecucionPIIP[CodigoProducto]=Reporte[[#This Row],[Cód. Prod.]]),""))} -> 202500000050554, 202600000000593, 202600000007861, 202600000008787, 202600000012764 | J14: =SUMIFS(CUIPO_datos_abiertos[COMPROMISOS],CUIPO_datos_abiertos[COD_PROGRAMATICO_MGA],Reporte[[#This Row],[Cód. Prod.]],CUIPO_datos_abiertos[PERIODO],$B$1) -> 4414341532 | K14: =SUMIFS(CUIPO_datos_abiertos[OBLIGACIONES],CUIPO_datos_abiertos[COD_PROGRAMATICO_MGA],Reporte[[#This Row],[Cód. Prod.]],CUIPO_datos_abiertos[PERIODO],$B$1) -> 4414341532 | L14: =IF(AND(Reporte[[#This Row],[Programación Física de la Meta]]=0,Reporte[[#This Row],[Ejecución Física PIIP]]<>0,Reporte[[#This Row],[Obligaciones (CUIPO)]]<>0),"Excluidos",IF(AND(Reporte[[#This Row],[Programación Física de la Meta]]<>0,Reporte[[#This Row],[Ejecución Física PIIP]]<>0,Reporte[[#This Row],[Obligaciones (CUIPO)]]<>0),"Aporta al calculo","")) -> Aporta al calculo | M14: =IF(Reporte[[#This Row],[¿Se tiene en cuenta para el calculo?]]="Aporta al calculo",Reporte[[#This Row],[Ejecución Física PIIP]]/Reporte[[#This Row],[Programación Física de la Meta]],"") -> 54.475657 | N14: =IF(Reporte[[#This Row],[¿Se tiene en cuenta para el calculo?]]="Aporta al calculo",IF(Reporte[[#This Row],[Avance físico (%)]]>1,1,Reporte[[#This Row],[Avance físico (%)]]),"") -> 1 | O14: =IF(Reporte[[#This Row],[¿Se tiene en cuenta para el calculo?]]="Aporta al calculo",Reporte[[#This Row],[Obligaciones (CUIPO)]]/$D$1,"") -> 0.0068763849 | P14: =IF(Reporte[[#This Row],[¿Se tiene en cuenta para el calculo?]]="Aporta al calculo",Reporte[[#This Row],[Avance ajustado (%)]]*Reporte[[#This Row],[Ponderador (wi)]],"") -> 0.0068763849
A15: 4599002 | B15: Servicio de saneamiento fiscal y financiero | C15: 459900200 | D15: Programa de sanemiento fiscal y financiero ejecutado | E15: {=_xlfn._xlws.FILTER(PI_SISPT_ProgramacionFisica[Prog. Fís.],(PI_SISPT_ProgramacionFisica[Cód. Prod.]=Reporte[[#This Row],[Cód. Prod.]])*(PI_SISPT_ProgramacionFisica[Vigencia]=LEFT('Reporte'!$B$1,4)))} -> 1 | F15: =SUMIFS(EjecucionPIIP[AvanceEjecutado],EjecucionPIIP[CodigoProducto],Reporte[[#This Row],[Cód. Prod.]],EjecucionPIIP[Periodo],$B$1,EjecucionPIIP[AvanceEjecutado],"<>0") -> 61.71 | G15: {=_xlfn._xlws.FILTER(ReporteEficacia[Meta ejecutada],(ReporteEficacia[Código producto]=Reporte[[#This Row],[Cód. Prod.]])*(ReporteEficacia[Periodo]='Reporte'!$B$1))} -> #VALUE! | H15: =IF(Reporte[[#This Row],[Ejecución Física PIIP]]=Reporte[[#This Row],[Eje. Fís. SISPT]],"Coincide","No coincide") -> #VALUE! | I15: {=_xlfn.TEXTJOIN(", ",TRUE,_xlfn._xlws.FILTER(EjecucionPIIP[Bpin],(EjecucionPIIP[Periodo]='Reporte'!$B$1)*(EjecucionPIIP[CodigoProducto]=Reporte[[#This Row],[Cód. Prod.]]),""))} -> 202500000032612, 202500000038150 | J15: =SUMIFS(CUIPO_datos_abiertos[COMPROMISOS],CUIPO_datos_abiertos[COD_PROGRAMATICO_MGA],Reporte[[#This Row],[Cód. Prod.]],CUIPO_datos_abiertos[PERIODO],$B$1) -> 3810249058 | K15: =SUMIFS(CUIPO_datos_abiertos[OBLIGACIONES],CUIPO_datos_abiertos[COD_PROGRAMATICO_MGA],Reporte[[#This Row],[Cód. Prod.]],CUIPO_datos_abiertos[PERIODO],$B$1) -> 3582249058 | L15: =IF(AND(Reporte[[#This Row],[Programación Física de la Meta]]=0,Reporte[[#This Row],[Ejecución Física PIIP]]<>0,Reporte[[#This Row],[Obligaciones (CUIPO)]]<>0),"Excluidos",IF(AND(Reporte[[#This Row],[Programación Física de la Meta]]<>0,Reporte[[#This Row],[Ejecución Física PIIP]]<>0,Reporte[[#This Row],[Obligaciones (CUIPO)]]<>0),"Aporta al calculo","")) -> Aporta al calculo | M15: =IF(Reporte[[#This Row],[¿Se tiene en cuenta para el calculo?]]="Aporta al calculo",Reporte[[#This Row],[Ejecución Física PIIP]]/Reporte[[#This Row],[Programación Física de la Meta]],"") -> 61.71 | N15: =IF(Reporte[[#This Row],[¿Se tiene en cuenta para el calculo?]]="Aporta al calculo",IF(Reporte[[#This Row],[Avance físico (%)]]>1,1,Reporte[[#This Row],[Avance físico (%)]]),"") -> 1 | O15: =IF(Reporte[[#This Row],[¿Se tiene en cuenta para el calculo?]]="Aporta al calculo",Reporte[[#This Row],[Obligaciones (CUIPO)]]/$D$1,"") -> 0.0055802034 | P15: =IF(Reporte[[#This Row],[¿Se tiene en cuenta para el calculo?]]="Aporta al calculo",Reporte[[#This Row],[Avance ajustado (%)]]*Reporte[[#This Row],[Ponderador (wi)]],"") -> 0.0055802034
A16: 2102058 | B16: Unidades de generación fotovoltaica de energía eléctrica instaladas | C16: 210205800 | D16: Unidades de generación fotovoltaica de energía eléctrica instaladas | E16: {=_xlfn._xlws.FILTER(PI_SISPT_ProgramacionFisica[Prog. Fís.],(PI_SISPT_ProgramacionFisica[Cód. Prod.]=Reporte[[#This Row],[Cód. Prod.]])*(PI_SISPT_ProgramacionFisica[Vigencia]=LEFT('Reporte'!$B$1,4)))} -> 470 | F16: =SUMIFS(EjecucionPIIP[AvanceEjecutado],EjecucionPIIP[CodigoProducto],Reporte[[#This Row],[Cód. Prod.]],EjecucionPIIP[Periodo],$B$1,EjecucionPIIP[AvanceEjecutado],"<>0") -> 60 | G16: {=_xlfn._xlws.FILTER(ReporteEficacia[Meta ejecutada],(ReporteEficacia[Código producto]=Reporte[[#This Row],[Cód. Prod.]])*(ReporteEficacia[Periodo]='Reporte'!$B$1))} -> #VALUE! | H16: =IF(Reporte[[#This Row],[Ejecución Física PIIP]]=Reporte[[#This Row],[Eje. Fís. SISPT]],"Coincide","No coincide") -> #VALUE! | I16: {=_xlfn.TEXTJOIN(", ",TRUE,_xlfn._xlws.FILTER(EjecucionPIIP[Bpin],(EjecucionPIIP[Periodo]='Reporte'!$B$1)*(EjecucionPIIP[CodigoProducto]=Reporte[[#This Row],[Cód. Prod.]]),""))} -> 2024002700131, 202500000034777 | J16: =SUMIFS(CUIPO_datos_abiertos[COMPROMISOS],CUIPO_datos_abiertos[COD_PROGRAMATICO_MGA],Reporte[[#This Row],[Cód. Prod.]],CUIPO_datos_abiertos[PERIODO],$B$1) -> 3548957101 | K16: =SUMIFS(CUIPO_datos_abiertos[OBLIGACIONES],CUIPO_datos_abiertos[COD_PROGRAMATICO_MGA],Reporte[[#This Row],[Cód. Prod.]],CUIPO_datos_abiertos[PERIODO],$B$1) -> 3120331456 | L16: =IF(AND(Reporte[[#This Row],[Programación Física de la Meta]]=0,Reporte[[#This Row],[Ejecución Física PIIP]]<>0,Reporte[[#This Row],[Obligaciones (CUIPO)]]<>0),"Excluidos",IF(AND(Reporte[[#This Row],[Programación Física de la Meta]]<>0,Reporte[[#This Row],[Ejecución Física PIIP]]<>0,Reporte[[#This Row],[Obligaciones (CUIPO)]]<>0),"Aporta al calculo","")) -> Aporta al calculo | M16: =IF(Reporte[[#This Row],[¿Se tiene en cuenta para el calculo?]]="Aporta al calculo",Reporte[[#This Row],[Ejecución Física PIIP]]/Reporte[[#This Row],[Programación Física de la Meta]],"") -> 0.12765957 | N16: =IF(Reporte[[#This Row],[¿Se tiene en cuenta para el calculo?]]="Aporta al calculo",IF(Reporte[[#This Row],[Avance físico (%)]]>1,1,Reporte[[#This Row],[Avance físico (%)]]),"") -> 0.12765957 | O16: =IF(Reporte[[#This Row],[¿Se tiene en cuenta para el calculo?]]="Aporta al calculo",Reporte[[#This Row],[Obligaciones (CUIPO)]]/$D$1,"") -> 0.004860657 | P16: =IF(Reporte[[#This Row],[¿Se tiene en cuenta para el calculo?]]="Aporta al calculo",Reporte[[#This Row],[Avance ajustado (%)]]*Reporte[[#This Row],[Ponderador (wi)]],"") -> 0.00062050941
A17: 3301053 | B17: Servicio de promoción de actividades culturales | C17: 330105300 | D17: Eventos de promoción de actividades culturales realizados | E17: {=_xlfn._xlws.FILTER(PI_SISPT_ProgramacionFisica[Prog. Fís.],(PI_SISPT_ProgramacionFisica[Cód. Prod.]=Reporte[[#This Row],[Cód. Prod.]])*(PI_SISPT_ProgramacionFisica[Vigencia]=LEFT('Reporte'!$B$1,4)))} -> 43 | F17: =SUMIFS(EjecucionPIIP[AvanceEjecutado],EjecucionPIIP[CodigoProducto],Reporte[[#This Row],[Cód. Prod.]],EjecucionPIIP[Periodo],$B$1,EjecucionPIIP[AvanceEjecutado],"<>0") -> 5 | G17: {=_xlfn._xlws.FILTER(ReporteEficacia[Meta ejecutada],(ReporteEficacia[Código producto]=Reporte[[#This Row],[Cód. Prod.]])*(ReporteEficacia[Periodo]='Reporte'!$B$1))} -> #VALUE! | H17: =IF(Reporte[[#This Row],[Ejecución Física PIIP]]=Reporte[[#This Row],[Eje. Fís. SISPT]],"Coincide","No coincide") -> #VALUE! | I17: {=_xlfn.TEXTJOIN(", ",TRUE,_xlfn._xlws.FILTER(EjecucionPIIP[Bpin],(EjecucionPIIP[Periodo]='Reporte'!$B$1)*(EjecucionPIIP[CodigoProducto]=Reporte[[#This Row],[Cód. Prod.]]),""))} -> 202600000001594 | J17: =SUMIFS(CUIPO_datos_abiertos[COMPROMISOS],CUIPO_datos_abiertos[COD_PROGRAMATICO_MGA],Reporte[[#This Row],[Cód. Prod.]],CUIPO_datos_abiertos[PERIODO],$B$1) -> 2589826566 | K17: =SUMIFS(CUIPO_datos_abiertos[OBLIGACIONES],CUIPO_datos_abiertos[COD_PROGRAMATICO_MGA],Reporte[[#This Row],[Cód. Prod.]],CUIPO_datos_abiertos[PERIODO],$B$1) -> 2589826566 | L17: =IF(AND(Reporte[[#This Row],[Programación Física de la Meta]]=0,Reporte[[#This Row],[Ejecución Física PIIP]]<>0,Reporte[[#This Row],[Obligaciones (CUIPO)]]<>0),"Excluidos",IF(AND(Reporte[[#This Row],[Programación Física de la Meta]]<>0,Reporte[[#This Row],[Ejecución Física PIIP]]<>0,Reporte[[#This Row],[Obligaciones (CUIPO)]]<>0),"Aporta al calculo","")) -> Aporta al calculo | M17: =IF(Reporte[[#This Row],[¿Se tiene en cuenta para el calculo?]]="Aporta al calculo",Reporte[[#This Row],[Ejecución Física PIIP]]/Reporte[[#This Row],[Programación Física de la Meta]],"") -> 0.11627907 | N17: =IF(Reporte[[#This Row],[¿Se tiene en cuenta para el calculo?]]="Aporta al calculo",IF(Reporte[[#This Row],[Avance físico (%)]]>1,1,Reporte[[#This Row],[Avance físico (%)]]),"") -> 0.11627907 | O17: =IF(Reporte[[#This Row],[¿Se tiene en cuenta para el calculo?]]="Aporta al calculo",Reporte[[#This Row],[Obligaciones (CUIPO)]]/$D$1,"") -> 0.0040342697 | P17: =IF(Reporte[[#This Row],[¿Se tiene en cuenta para el calculo?]]="Aporta al calculo",Reporte[[#This Row],[Avance ajustado (%)]]*Reporte[[#This Row],[Ponderador (wi)]],"") -> 0.00046910113
... A291: 1702007 | B291: Servicio de apoyo financiero para proyectos productivos | C291: 170200700 | D291: Proyectos productivos cofinanciados | E291: {=_xlfn._xlws.FILTER(PI_SISPT_ProgramacionFisica[Prog. Fís.],(PI_SISPT_ProgramacionFisica[Cód. Prod.]=Reporte[[#This Row],[Cód. Prod.]])*(PI_SISPT_ProgramacionFisica[Vigencia]=LEFT('Reporte'!$B$1,4)))} -> 4 | F291: =SUMIFS(EjecucionPIIP[AvanceEjecutado],EjecucionPIIP[CodigoProducto],Reporte[[#This Row],[Cód. Prod.]],EjecucionPIIP[Periodo],$B$1,EjecucionPIIP[AvanceEjecutado],"<>0") -> 0 | G291: {=_xlfn._xlws.FILTER(ReporteEficacia[Meta ejecutada],(ReporteEficacia[Código producto]=Reporte[[#This Row],[Cód. Prod.]])*(ReporteEficacia[Periodo]='Reporte'!$B$1))} -> #VALUE! | H291: =IF(Reporte[[#This Row],[Ejecución Física PIIP]]=Reporte[[#This Row],[Eje. Fís. SISPT]],"Coincide","No coincide") -> #VALUE! | I291: {=_xlfn.TEXTJOIN(", ",TRUE,_xlfn._xlws.FILTER(EjecucionPIIP[Bpin],(EjecucionPIIP[Periodo]='Reporte'!$B$1)*(EjecucionPIIP[CodigoProducto]=Reporte[[#This Row],[Cód. Prod.]]),""))} | J291: =SUMIFS(CUIPO_datos_abiertos[COMPROMISOS],CUIPO_datos_abiertos[COD_PROGRAMATICO_MGA],Reporte[[#This Row],[Cód. Prod.]],CUIPO_datos_abiertos[PERIODO],$B$1) -> 0 | K291: =SUMIFS(CUIPO_datos_abiertos[OBLIGACIONES],CUIPO_datos_abiertos[COD_PROGRAMATICO_MGA],Reporte[[#This Row],[Cód. Prod.]],CUIPO_datos_abiertos[PERIODO],$B$1) -> 0 | L291: =IF(AND(Reporte[[#This Row],[Programación Física de la Meta]]=0,Reporte[[#This Row],[Ejecución Física PIIP]]<>0,Reporte[[#This Row],[Obligaciones (CUIPO)]]<>0),"Excluidos",IF(AND(Reporte[[#This Row],[Programación Física de la Meta]]<>0,Reporte[[#This Row],[Ejecución Física PIIP]]<>0,Reporte[[#This Row],[Obligaciones (CUIPO)]]<>0),"Aporta al calculo","")) | M291: =IF(Reporte[[#This Row],[¿Se tiene en cuenta para el calculo?]]="Aporta al calculo",Reporte[[#This Row],[Ejecución Física PIIP]]/Reporte[[#This Row],[Programación Física de la Meta]],"") | N291: =IF(Reporte[[#This Row],[¿Se tiene en cuenta para el calculo?]]="Aporta al calculo",IF(Reporte[[#This Row],[Avance físico (%)]]>1,1,Reporte[[#This Row],[Avance físico (%)]]),"") | O291: =IF(Reporte[[#This Row],[¿Se tiene en cuenta para el calculo?]]="Aporta al calculo",Reporte[[#This Row],[Obligaciones (CUIPO)]]/$D$1,"") | P291: =IF(Reporte[[#This Row],[¿Se tiene en cuenta para el calculo?]]="Aporta al calculo",Reporte[[#This Row],[Avance ajustado (%)]]*Reporte[[#This Row],[Ponderador (wi)]],"")

Sheet Parametros
A1: PERIODO | C1: Periodo | D1: Nombre | E1: En mayuscula
A2: 20251201 | C2: 20250301 | D2: Primer trimestre 2025 | E2: =UPPER(TablaPeriodos[[#This Row],[Nombre]]) -> PRIMER TRIMESTRE 2025
A3: 20260301 | C3: 20250601 | D3: Segundo trimestre 2025 | E3: =UPPER(TablaPeriodos[[#This Row],[Nombre]]) -> SEGUNDO TRIMESTRE 2025
A4: 20260601 | C4: 20250901 | D4: Tercer trimestre 2025 | E4: =UPPER(TablaPeriodos[[#This Row],[Nombre]]) -> TERCER TRIMESTRE 2025
C5: 20251201 | D5: Cuarto trimestre 2025 | E5: =UPPER(TablaPeriodos[[#This Row],[Nombre]]) -> CUARTO TRIMESTRE 2025
C6: 20260301 | D6: Primer trimestre 2026 | E6: =UPPER(TablaPeriodos[[#This Row],[Nombre]]) -> PRIMER TRIMESTRE 2026
C7: 20260601 | D7: Segundo trimestre 2026 | E7: =UPPER(TablaPeriodos[[#This Row],[Nombre]]) -> SEGUNDO TRIMESTRE 2026
C8: 20260901 | D8: Tercer trimestre 2026 | E8: =UPPER(TablaPeriodos[[#This Row],[Nombre]]) -> TERCER TRIMESTRE 2026
C9: 20261201 | D9: Cuarto trimestre 2026 | E9: =UPPER(TablaPeriodos[[#This Row],[Nombre]]) -> CUARTO TRIMESTRE 2026
C10: 20270301 | D10: Primer trimestre 2027 | E10: =UPPER(TablaPeriodos[[#This Row],[Nombre]]) -> PRIMER TRIMESTRE 2027
C11: 20270601 | D11: Segundo trimestre 2027 | E11: =UPPER(TablaPeriodos[[#This Row],[Nombre]]) -> SEGUNDO TRIMESTRE 2027
C12: 20270901 | D12: Tercer trimestre 2027 | E12: =UPPER(TablaPeriodos[[#This Row],[Nombre]]) -> TERCER TRIMESTRE 2027
C13: 20271201 | D13: Cuarto trimestre 2027 | E13: =UPPER(TablaPeriodos[[#This Row],[Nombre]]) -> CUARTO TRIMESTRE 2027

Sheet Bono_1
A1: Código Programa presupuestal | B1: Programa Presupuestal | C1: Programación Financiera | D1: Obligaciones | E1: Mínimo | F1: Máximo | G1: Razón (Mínimo/Máximo) | H1: Ponderación (w) | I1: Aporte
A2: 2201 | B2: Calidad, cobertura y fortalecimiento de la educación inicial, prescolar, básica y media | C2: =SUMIFS(PPI_cuerpo_colegiado[Programación Financiera],PPI_cuerpo_colegiado[Código Programa presupuestal],Tabla15[[#This Row],[Código Programa presupuestal]],PPI_cuerpo_colegiado[Vigencia],LEFT('Reporte'!$B$1,4)) -> 7.2983306e+11 | D2: =SUMIFS(CUIPO_datos_abiertos[OBLIGACIONES],CUIPO_datos_abiertos[COD_PROGAMA_MGA],Tabla15[[#This Row],[Código Programa presupuestal]],CUIPO_datos_abiertos[PERIODO],'Reporte'!$B$1) -> 381728805073 | E2: =MIN(Tabla15[[#This Row],[Programación Financiera]:[Obligaciones]]) -> 381728805073 | F2: =MAX(Tabla15[[#This Row],[Programación Financiera]:[Obligaciones]]) -> 7.2983306e+11 | G2: =IFERROR(Tabla15[[#This Row],[Mínimo]]/Tabla15[[#This Row],[Máximo]],0) -> 0.52303578 | H2: =IF(Tabla15[[#This Row],[Razón (Mínimo/Máximo)]]>=0.5,Tabla15[[#This Row],[Obligaciones]]/'Reporte'!$D$1,"") -> 0.59463324 | I2: =IF(ISNUMBER(Tabla15[[#This Row],[Ponderación (w)]]),Tabla15[[#This Row],[Razón (Mínimo/Máximo)]]*Tabla15[[#This Row],[Ponderación (w)]],"") -> 0.31101446
A3: 4599 | B3: Fortalecimiento a la gestión y dirección de la administración pública territorial | C3: =SUMIFS(PPI_cuerpo_colegiado[Programación Financiera],PPI_cuerpo_colegiado[Código Programa presupuestal],Tabla15[[#This Row],[Código Programa presupuestal]],PPI_cuerpo_colegiado[Vigencia],LEFT('Reporte'!$B$1,4)) -> 3.4582773e+10 | D3: =SUMIFS(CUIPO_datos_abiertos[OBLIGACIONES],CUIPO_datos_abiertos[COD_PROGAMA_MGA],Tabla15[[#This Row],[Código Programa presupuestal]],CUIPO_datos_abiertos[PERIODO],'Reporte'!$B$1) -> 23874162737 | E3: =MIN(Tabla15[[#This Row],[Programación Financiera]:[Obligaciones]]) -> 23874162737 | F3: =MAX(Tabla15[[#This Row],[Programación Financiera]:[Obligaciones]]) -> 3.4582773e+10 | G3: =IFERROR(Tabla15[[#This Row],[Mínimo]]/Tabla15[[#This Row],[Máximo]],0) -> 0.69034841 | H3: =IF(Tabla15[[#This Row],[Razón (Mínimo/Máximo)]]>=0.5,Tabla15[[#This Row],[Obligaciones]]/'Reporte'!$D$1,"") -> 0.037189676 | I3: =IF(ISNUMBER(Tabla15[[#This Row],[Ponderación (w)]]),Tabla15[[#This Row],[Razón (Mínimo/Máximo)]]*Tabla15[[#This Row],[Ponderación (w)]],"") -> 0.025673834
A4: 3502 | B4: Productividad y competitividad de las empresas colombianas | C4: =SUMIFS(PPI_cuerpo_colegiado[Programación Financiera],PPI_cuerpo_colegiado[Código Programa presupuestal],Tabla15[[#This Row],[Código Programa presupuestal]],PPI_cuerpo_colegiado[Vigencia],LEFT('Reporte'!$B$1,4)) -> 27942000000 | D4: =SUMIFS(CUIPO_datos_abiertos[OBLIGACIONES],CUIPO_datos_abiertos[COD_PROGAMA_MGA],Tabla15[[#This Row],[Código Programa presupuestal]],CUIPO_datos_abiertos[PERIODO],'Reporte'!$B$1) -> 2448642029 | E4: =MIN(Tabla15[[#This Row],[Programación Financiera]:[Obligaciones]]) -> 2448642029 | F4: =MAX(Tabla15[[#This Row],[Programación Financiera]:[Obligaciones]]) -> 27942000000 | G4: =IFERROR(Tabla15[[#This Row],[Mínimo]]/Tabla15[[#This Row],[Máximo]],0) -> 0.087633027 | H4: =IF(Tabla15[[#This Row],[Razón (Mínimo/Máximo)]]>=0.5,Tabla15[[#This Row],[Obligaciones]]/'Reporte'!$D$1,"") | I4: =IF(ISNUMBER(Tabla15[[#This Row],[Ponderación (w)]]),Tabla15[[#This Row],[Razón (Mínimo/Máximo)]]*Tabla15[[#This Row],[Ponderación (w)]],"")
A5: 4301 | B5: Fomento a la recreación, la actividad física y el deporte para desarrollar entornos de convivencia y paz | C5: =SUMIFS(PPI_cuerpo_colegiado[Programación Financiera],PPI_cuerpo_colegiado[Código Programa presupuestal],Tabla15[[#This Row],[Código Programa presupuestal]],PPI_cuerpo_colegiado[Vigencia],LEFT('Reporte'!$B$1,4)) -> 5760125000 | D5: =SUMIFS(CUIPO_datos_abiertos[OBLIGACIONES],CUIPO_datos_abiertos[COD_PROGAMA_MGA],Tabla15[[#This Row],[Código Programa presupuestal]],CUIPO_datos_abiertos[PERIODO],'Reporte'!$B$1) -> 6733146035 | E5: =MIN(Tabla15[[#This Row],[Programación Financiera]:[Obligaciones]]) -> 5760125000 | F5: =MAX(Tabla15[[#This Row],[Programación Financiera]:[Obligaciones]]) -> 6733146035 | G5: =IFERROR(Tabla15[[#This Row],[Mínimo]]/Tabla15[[#This Row],[Máximo]],0) -> 0.85548791 | H5: =IF(Tabla15[[#This Row],[Razón (Mínimo/Máximo)]]>=0.5,Tabla15[[#This Row],[Obligaciones]]/'Reporte'!$D$1,"") -> 0.010488473 | I5: =IF(ISNUMBER(Tabla15[[#This Row],[Ponderación (w)]]),Tabla15[[#This Row],[Razón (Mínimo/Máximo)]]*Tabla15[[#This Row],[Ponderación (w)]],"") -> 0.0089727622
A6: 1905 | B6: Salud pública | C6: =SUMIFS(PPI_cuerpo_colegiado[Programación Financiera],PPI_cuerpo_colegiado[Código Programa presupuestal],Tabla15[[#This Row],[Código Programa presupuestal]],PPI_cuerpo_colegiado[Vigencia],LEFT('Reporte'!$B$1,4)) -> 7.4058745e+09 | D6: =SUMIFS(CUIPO_datos_abiertos[OBLIGACIONES],CUIPO_datos_abiertos[COD_PROGAMA_MGA],Tabla15[[#This Row],[Código Programa presupuestal]],CUIPO_datos_abiertos[PERIODO],'Reporte'!$B$1) -> 1844794471 | E6: =MIN(Tabla15[[#This Row],[Programación Financiera]:[Obligaciones]]) -> 1844794471 | F6: =MAX(Tabla15[[#This Row],[Programación Financiera]:[Obligaciones]]) -> 7.4058745e+09 | G6: =IFERROR(Tabla15[[#This Row],[Mínimo]]/Tabla15[[#This Row],[Máximo]],0) -> 0.2490988 | H6: =IF(Tabla15[[#This Row],[Razón (Mínimo/Máximo)]]>=0.5,Tabla15[[#This Row],[Obligaciones]]/'Reporte'!$D$1,"") | I6: =IF(ISNUMBER(Tabla15[[#This Row],[Ponderación (w)]]),Tabla15[[#This Row],[Razón (Mínimo/Máximo)]]*Tabla15[[#This Row],[Ponderación (w)]],"")
A7: 4101 | B7: Atención, asistencia y reparación integral a las víctimas | C7: =SUMIFS(PPI_cuerpo_colegiado[Programación Financiera],PPI_cuerpo_colegiado[Código Programa presupuestal],Tabla15[[#This Row],[Código Programa presupuestal]],PPI_cuerpo_colegiado[Vigencia],LEFT('Reporte'!$B$1,4)) -> 718000000 | D7: =SUMIFS(CUIPO_datos_abiertos[OBLIGACIONES],CUIPO_datos_abiertos[COD_PROGAMA_MGA],Tabla15[[#This Row],[Código Programa presupuestal]],CUIPO_datos_abiertos[PERIODO],'Reporte'!$B$1) -> 80459466 | E7: =MIN(Tabla15[[#This Row],[Programación Financiera]:[Obligaciones]]) -> 80459466 | F7: =MAX(Tabla15[[#This Row],[Programación Financiera]:[Obligaciones]]) -> 718000000 | G7: =IFERROR(Tabla15[[#This Row],[Mínimo]]/Tabla15[[#This Row],[Máximo]],0) -> 0.11206054 | H7: =IF(Tabla15[[#This Row],[Razón (Mínimo/Máximo)]]>=0.5,Tabla15[[#This Row],[Obligaciones]]/'Reporte'!$D$1,"") | I7: =IF(ISNUMBER(Tabla15[[#This Row],[Ponderación (w)]]),Tabla15[[#This Row],[Razón (Mínimo/Máximo)]]*Tabla15[[#This Row],[Ponderación (w)]],"")
A8: 0401 | B8: Levantamiento y actualización de información estadística de calidad | C8: =SUMIFS(PPI_cuerpo_colegiado[Programación Financiera],PPI_cuerpo_colegiado[Código Programa presupuestal],Tabla15[[#This Row],[Código Programa presupuestal]],PPI_cuerpo_colegiado[Vigencia],LEFT('Reporte'!$B$1,4)) -> 300000000 | D8: =SUMIFS(CUIPO_datos_abiertos[OBLIGACIONES],CUIPO_datos_abiertos[COD_PROGAMA_MGA],Tabla15[[#This Row],[Código Programa presupuestal]],CUIPO_datos_abiertos[PERIODO],'Reporte'!$B$1) -> 164000000 | E8: =MIN(Tabla15[[#This Row],[Programación Financiera]:[Obligaciones]]) -> 164000000 | F8: =MAX(Tabla15[[#This Row],[Programación Financiera]:[Obligaciones]]) -> 300000000 | G8: =IFERROR(Tabla15[[#This Row],[Mínimo]]/Tabla15[[#This Row],[Máximo]],0) -> 0.54666667 | H8: =IF(Tabla15[[#This Row],[Razón (Mínimo/Máximo)]]>=0.5,Tabla15[[#This Row],[Obligaciones]]/'Reporte'!$D$1,"") -> 0.00025546893 | I8: =IF(ISNUMBER(Tabla15[[#This Row],[Ponderación (w)]]),Tabla15[[#This Row],[Razón (Mínimo/Máximo)]]*Tabla15[[#This Row],[Ponderación (w)]],"") -> 0.00013965635
A9: 2102 | B9: Consolidación productiva del sector de energía eléctrica | C9: =SUMIFS(PPI_cuerpo_colegiado[Programación Financiera],PPI_cuerpo_colegiado[Código Programa presupuestal],Tabla15[[#This Row],[Código Programa presupuestal]],PPI_cuerpo_colegiado[Vigencia],LEFT('Reporte'!$B$1,4)) -> 29696000000 | D9: =SUMIFS(CUIPO_datos_abiertos[OBLIGACIONES],CUIPO_datos_abiertos[COD_PROGAMA_MGA],Tabla15[[#This Row],[Código Programa presupuestal]],CUIPO_datos_abiertos[PERIODO],'Reporte'!$B$1) -> 3120331456 | E9: =MIN(Tabla15[[#This Row],[Programación Financiera]:[Obligaciones]]) -> 3120331456 | F9: =MAX(Tabla15[[#This Row],[Programación Financiera]:[Obligaciones]]) -> 29696000000 | G9: =IFERROR(Tabla15[[#This Row],[Mínimo]]/Tabla15[[#This Row],[Máximo]],0) -> 0.10507582 | H9: =IF(Tabla15[[#This Row],[Razón (Mínimo/Máximo)]]>=0.5,Tabla15[[#This Row],[Obligaciones]]/'Reporte'!$D$1,"") | I9: =IF(ISNUMBER(Tabla15[[#This Row],[Ponderación (w)]]),Tabla15[[#This Row],[Razón (Mínimo/Máximo)]]*Tabla15[[#This Row],[Ponderación (w)]],"")
A10: 1906 | B10: Aseguramiento y prestación integral de servicios de salud | C10: =SUMIFS(PPI_cuerpo_colegiado[Programación Financiera],PPI_cuerpo_colegiado[Código Programa presupuestal],Tabla15[[#This Row],[Código Programa presupuestal]],PPI_cuerpo_colegiado[Vigencia],LEFT('Reporte'!$B$1,4)) -> 9.9032769e+10 | D10: =SUMIFS(CUIPO_datos_abiertos[OBLIGACIONES],CUIPO_datos_abiertos[COD_PROGAMA_MGA],Tabla15[[#This Row],[Código Programa presupuestal]],CUIPO_datos_abiertos[PERIODO],'Reporte'!$B$1) -> 31066371199 | E10: =MIN(Tabla15[[#This Row],[Programación Financiera]:[Obligaciones]]) -> 31066371199 | F10: =MAX(Tabla15[[#This Row],[Programación Financiera]:[Obligaciones]]) -> 9.9032769e+10 | G10: =IFERROR(Tabla15[[#This Row],[Mínimo]]/Tabla15[[#This Row],[Máximo]],0) -> 0.31369789 | H10: =IF(Tabla15[[#This Row],[Razón (Mínimo/Máximo)]]>=0.5,Tabla15[[#This Row],[Obligaciones]]/'Reporte'!$D$1,"") | I10: =IF(ISNUMBER(Tabla15[[#This Row],[Ponderación (w)]]),Tabla15[[#This Row],[Razón (Mínimo/Máximo)]]*Tabla15[[#This Row],[Ponderación (w)]],"")
A11: 4003 | B11: Acceso de la población a los servicios de agua potable y saneamiento básico | C11: =SUMIFS(PPI_cuerpo_colegiado[Programación Financiera],PPI_cuerpo_colegiado[Código Programa presupuestal],Tabla15[[#This Row],[Código Programa presupuestal]],PPI_cuerpo_colegiado[Vigencia],LEFT('Reporte'!$B$1,4)) -> 1.4796347e+10 | D11: =SUMIFS(CUIPO_datos_abiertos[OBLIGACIONES],CUIPO_datos_abiertos[COD_PROGAMA_MGA],Tabla15[[#This Row],[Código Programa presupuestal]],CUIPO_datos_abiertos[PERIODO],'Reporte'!$B$1) -> 2185764639 | E11: =MIN(Tabla15[[#This Row],[Programación Financiera]:[Obligaciones]]) -> 2185764639 | F11: =MAX(Tabla15[[#This Row],[Programación Financiera]:[Obligaciones]]) -> 1.4796347e+10 | G11: =IFERROR(Tabla15[[#This Row],[Mínimo]]/Tabla15[[#This Row],[Máximo]],0) -> 0.14772326 | H11: =IF(Tabla15[[#This Row],[Razón (Mínimo/Máximo)]]>=0.5,Tabla15[[#This Row],[Obligaciones]]/'Reporte'!$D$1,"") | I11: =IF(ISNUMBER(Tabla15[[#This Row],[Ponderación (w)]]),Tabla15[[#This Row],[Razón (Mínimo/Máximo)]]*Tabla15[[#This Row],[Ponderación (w)]],"")
A12: 2402 | B12: Infraestructura red vial regional | C12: =SUMIFS(PPI_cuerpo_colegiado[Programación Financiera],PPI_cuerpo_colegiado[Código Programa presupuestal],Tabla15[[#This Row],[Código Programa presupuestal]],PPI_cuerpo_colegiado[Vigencia],LEFT('Reporte'!$B$1,4)) -> 23940000000 | D12: =SUMIFS(CUIPO_datos_abiertos[OBLIGACIONES],CUIPO_datos_abiertos[COD_PROGAMA_MGA],Tabla15[[#This Row],[Código Programa presupuestal]],CUIPO_datos_abiertos[PERIODO],'Reporte'!$B$1) -> 25640135713 | E12: =MIN(Tabla15[[#This Row],[Programación Financiera]:[Obligaciones]]) -> 23940000000 | F12: =MAX(Tabla15[[#This Row],[Programación Financiera]:[Obligaciones]]) -> 25640135713 | G12: =IFERROR(Tabla15[[#This Row],[Mínimo]]/Tabla15[[#This Row],[Máximo]],0) -> 0.93369241 | H12: =IF(Tabla15[[#This Row],[Razón (Mínimo/Máximo)]]>=0.5,Tabla15[[#This Row],[Obligaciones]]/'Reporte'!$D$1,"") -> 0.039940599 | I12: =IF(ISNUMBER(Tabla15[[#This Row],[Ponderación (w)]]),Tabla15[[#This Row],[Razón (Mínimo/Máximo)]]*Tabla15[[#This Row],[Ponderación (w)]],"") -> 0.037292234
A13: 4501 | B13: Fortalecimiento de la convivencia y la seguridad ciudadana | C13: =SUMIFS(PPI_cuerpo_colegiado[Programación Financiera],PPI_cuerpo_colegiado[Código Programa presupuestal],Tabla15[[#This Row],[Código Programa presupuestal]],PPI_cuerpo_colegiado[Vigencia],LEFT('Reporte'!$B$1,4)) -> 5661500000 | D13: =SUMIFS(CUIPO_datos_abiertos[OBLIGACIONES],CUIPO_datos_abiertos[COD_PROGAMA_MGA],Tabla15[[#This Row],[Código Programa presupuestal]],CUIPO_datos_abiertos[PERIODO],'Reporte'!$B$1) -> 7825133773 | E13: =MIN(Tabla15[[#This Row],[Programación Financiera]:[Obligaciones]]) -> 5661500000 | F13: =MAX(Tabla15[[#This Row],[Programación Financiera]:[Obligaciones]]) -> 7825133773 | G13: =IFERROR(Tabla15[[#This Row],[Mínimo]]/Tabla15[[#This Row],[Máximo]],0) -> 0.72350201 | H13: =IF(Tabla15[[#This Row],[Razón (Mínimo/Máximo)]]>=0.5,Tabla15[[#This Row],[Obligaciones]]/'Reporte'!$D$1,"") -> 0.012189504 | I13: =IF(ISNUMBER(Tabla15[[#This Row],[Ponderación (w)]]),Tabla15[[#This Row],[Razón (Mínimo/Máximo)]]*Tabla15[[#This Row],[Ponderación (w)]],"") -> 0.0088191303
... A55: 4002 | B55: Ordenamiento territorial y desarrollo urbano | C55: =SUMIFS(PPI_cuerpo_colegiado[Programación Financiera],PPI_cuerpo_colegiado[Código Programa presupuestal],Tabla15[[#This Row],[Código Programa presupuestal]],PPI_cuerpo_colegiado[Vigencia],LEFT('Reporte'!$B$1,4)) -> 0 | D55: =SUMIFS(CUIPO_datos_abiertos[OBLIGACIONES],CUIPO_datos_abiertos[COD_PROGAMA_MGA],Tabla15[[#This Row],[Código Programa presupuestal]],CUIPO_datos_abiertos[PERIODO],'Reporte'!$B$1) -> 0 | E55: =MIN(Tabla15[[#This Row],[Programación Financiera]:[Obligaciones]]) -> 0 | F55: =MAX(Tabla15[[#This Row],[Programación Financiera]:[Obligaciones]]) -> 0 | G55: =IFERROR(Tabla15[[#This Row],[Mínimo]]/Tabla15[[#This Row],[Máximo]],0) -> 0 | H55: =IF(Tabla15[[#This Row],[Razón (Mínimo/Máximo)]]>=0.5,Tabla15[[#This Row],[Obligaciones]]/'Reporte'!$D$1,"") | I55: =IF(ISNUMBER(Tabla15[[#This Row],[Ponderación (w)]]),Tabla15[[#This Row],[Razón (Mínimo/Máximo)]]*Tabla15[[#This Row],[Ponderación (w)]],"")

Sheet Bono_2
B1: Se contabilizan todos los productos de PI cargado en SISPT, independiente de si estan programados o no en la vigencia
B2: Cuipo obligaciones diferentes a cero
B3: Piip productos con reporte de ejecución en la vigencia
B4: Cód. Prod. | C4: Está en SISPT | D4: Está en PIIP | E4: Esta en CUIPO | F4: Aplicabilidad bono 4 | V4: Región | W4: Conteo
B5: {=_xlfn.LET(_xlpm.productos_cuipo,_xlfn.UNIQUE(_xlfn._xlws.FILTER(CUIPO_datos_abiertos[COD_PROGRAMATICO_MGA],(CUIPO_datos_abiertos[ES_PRODUCTO_VALIDO]="VALIDO")*(CUIPO_datos_abiertos[PERIODO]='Reporte'!$B$1))),_xlpm.productos_pisistpt,_xlfn.UNIQUE(PI_SISPT_ProgramacionFisica[Cód. Prod.]),_xlpm.productos_piip,_xlfn.UNIQUE(_xlfn._xlws.FILTER(EjecucionPIIP[CodigoProducto],(EjecucionPIIP[Vigencia]=LEFT('Reporte'!$B$1,4))*(EjecucionPIIP[AvanceEjecutado]<>0))),_xlpm.apilado,_xlfn.UNIQUE(_xlfn.VSTACK(_xlpm.productos_cuipo,_xlpm.productos_piip,_xlpm.productos_pisistpt)),_xlpm.apilado)} -> 1903001 | C5: {=IF(ISNUMBER(VALUE(_xlfn.UNIQUE(_xlfn._xlws.FILTER(PI_SISPT_ProgramacionFisica[Cód. Prod.],PI_SISPT_ProgramacionFisica[Cód. Prod.]=Bono_2!B5,"")))),1,"")} | D5: {=IF(ISNUMBER(VALUE(_xlfn.UNIQUE(_xlfn._xlws.FILTER(EjecucionPIIP[CodigoProducto],(EjecucionPIIP[CodigoProducto]=Bono_2!B5)*(EjecucionPIIP[Vigencia]=LEFT('Reporte'!$B$1,4))*(EjecucionPIIP[AvanceEjecutado]<>0),"")))),1,"")} | E5: {=IF(ISNUMBER(VALUE(_xlfn.UNIQUE(_xlfn._xlws.FILTER(CUIPO_datos_abiertos[COD_PROGRAMATICO_MGA],(CUIPO_datos_abiertos[COD_PROGRAMATICO_MGA]=Bono_2!B5)*(CUIPO_datos_abiertos[PERIODO]='Reporte'!$B$1)*(CUIPO_datos_abiertos[OBLIGACIONES]<>0),"")))),1,"")} -> 1 | F5: =IF(SUM(C5:E5)=3,"Aplica","") | V5: Solo SISPT | W5: {=SUMPRODUCT(($C$5:$C$322=1)*($D$5:$D$322<>1)*($E$5:$E$322<>1))} -> 234
B6: 4599023 | C6: {=IF(ISNUMBER(VALUE(_xlfn.UNIQUE(_xlfn._xlws.FILTER(PI_SISPT_ProgramacionFisica[Cód. Prod.],PI_SISPT_ProgramacionFisica[Cód. Prod.]=Bono_2!B6,"")))),1,"")} -> 1 | D6: {=IF(ISNUMBER(VALUE(_xlfn.UNIQUE(_xlfn._xlws.FILTER(EjecucionPIIP[CodigoProducto],(EjecucionPIIP[CodigoProducto]=Bono_2!B6)*(EjecucionPIIP[Vigencia]=LEFT('Reporte'!$B$1,4))*(EjecucionPIIP[AvanceEjecutado]<>0),"")))),1,"")} -> 1 | E6: {=IF(ISNUMBER(VALUE(_xlfn.UNIQUE(_xlfn._xlws.FILTER(CUIPO_datos_abiertos[COD_PROGRAMATICO_MGA],(CUIPO_datos_abiertos[COD_PROGRAMATICO_MGA]=Bono_2!B6)*(CUIPO_datos_abiertos[PERIODO]='Reporte'!$B$1)*(CUIPO_datos_abiertos[OBLIGACIONES]<>0),"")))),1,"")} -> 1 | F6: =IF(SUM(C6:E6)=3,"Aplica","") -> Aplica | V6: Solo PIIP | W6: {=SUMPRODUCT(($C$5:$C$322<>1)*($D$5:$D$322=1)*($E$5:$E$322<>1))} -> 3
B7: 4104020 | C7: {=IF(ISNUMBER(VALUE(_xlfn.UNIQUE(_xlfn._xlws.FILTER(PI_SISPT_ProgramacionFisica[Cód. Prod.],PI_SISPT_ProgramacionFisica[Cód. Prod.]=Bono_2!B7,"")))),1,"")} -> 1 | D7: {=IF(ISNUMBER(VALUE(_xlfn.UNIQUE(_xlfn._xlws.FILTER(EjecucionPIIP[CodigoProducto],(EjecucionPIIP[CodigoProducto]=Bono_2!B7)*(EjecucionPIIP[Vigencia]=LEFT('Reporte'!$B$1,4))*(EjecucionPIIP[AvanceEjecutado]<>0),"")))),1,"")} -> 1 | E7: {=IF(ISNUMBER(VALUE(_xlfn.UNIQUE(_xlfn._xlws.FILTER(CUIPO_datos_abiertos[COD_PROGRAMATICO_MGA],(CUIPO_datos_abiertos[COD_PROGRAMATICO_MGA]=Bono_2!B7)*(CUIPO_datos_abiertos[PERIODO]='Reporte'!$B$1)*(CUIPO_datos_abiertos[OBLIGACIONES]<>0),"")))),1,"")} -> 1 | F7: =IF(SUM(C7:E7)=3,"Aplica","") -> Aplica | V7: Solo CUIPO | W7: {=SUMPRODUCT(($C$5:$C$322<>1)*($D$5:$D$322<>1)*($E$5:$E$322=1))} -> 24
B8: 4599002 | C8: {=IF(ISNUMBER(VALUE(_xlfn.UNIQUE(_xlfn._xlws.FILTER(PI_SISPT_ProgramacionFisica[Cód. Prod.],PI_SISPT_ProgramacionFisica[Cód. Prod.]=Bono_2!B8,"")))),1,"")} -> 1 | D8: {=IF(ISNUMBER(VALUE(_xlfn.UNIQUE(_xlfn._xlws.FILTER(EjecucionPIIP[CodigoProducto],(EjecucionPIIP[CodigoProducto]=Bono_2!B8)*(EjecucionPIIP[Vigencia]=LEFT('Reporte'!$B$1,4))*(EjecucionPIIP[AvanceEjecutado]<>0),"")))),1,"")} -> 1 | E8: {=IF(ISNUMBER(VALUE(_xlfn.UNIQUE(_xlfn._xlws.FILTER(CUIPO_datos_abiertos[COD_PROGRAMATICO_MGA],(CUIPO_datos_abiertos[COD_PROGRAMATICO_MGA]=Bono_2!B8)*(CUIPO_datos_abiertos[PERIODO]='Reporte'!$B$1)*(CUIPO_datos_abiertos[OBLIGACIONES]<>0),"")))),1,"")} -> 1 | F8: =IF(SUM(C8:E8)=3,"Aplica","") -> Aplica | V8: SISPT ∩ PIIP (sin CUIPO) | W8: {=SUMPRODUCT(($C$5:$C$322=1)*($D$5:$D$322=1)*($E$5:$E$322<>1))} -> 10
B9: 1906039 | C9: {=IF(ISNUMBER(VALUE(_xlfn.UNIQUE(_xlfn._xlws.FILTER(PI_SISPT_ProgramacionFisica[Cód. Prod.],PI_SISPT_ProgramacionFisica[Cód. Prod.]=Bono_2!B9,"")))),1,"")} | D9: {=IF(ISNUMBER(VALUE(_xlfn.UNIQUE(_xlfn._xlws.FILTER(EjecucionPIIP[CodigoProducto],(EjecucionPIIP[CodigoProducto]=Bono_2!B9)*(EjecucionPIIP[Vigencia]=LEFT('Reporte'!$B$1,4))*(EjecucionPIIP[AvanceEjecutado]<>0),"")))),1,"")} | E9: {=IF(ISNUMBER(VALUE(_xlfn.UNIQUE(_xlfn._xlws.FILTER(CUIPO_datos_abiertos[COD_PROGRAMATICO_MGA],(CUIPO_datos_abiertos[COD_PROGRAMATICO_MGA]=Bono_2!B9)*(CUIPO_datos_abiertos[PERIODO]='Reporte'!$B$1)*(CUIPO_datos_abiertos[OBLIGACIONES]<>0),"")))),1,"")} -> 1 | F9: =IF(SUM(C9:E9)=3,"Aplica","") | V9: SISPT ∩ CUIPO (sin PIIP) | W9: {=SUMPRODUCT(($C$5:$C$322=1)*($D$5:$D$322<>1)*($E$5:$E$322=1))} -> 23
B10: 2201071 | C10: {=IF(ISNUMBER(VALUE(_xlfn.UNIQUE(_xlfn._xlws.FILTER(PI_SISPT_ProgramacionFisica[Cód. Prod.],PI_SISPT_ProgramacionFisica[Cód. Prod.]=Bono_2!B10,"")))),1,"")} -> 1 | D10: {=IF(ISNUMBER(VALUE(_xlfn.UNIQUE(_xlfn._xlws.FILTER(EjecucionPIIP[CodigoProducto],(EjecucionPIIP[CodigoProducto]=Bono_2!B10)*(EjecucionPIIP[Vigencia]=LEFT('Reporte'!$B$1,4))*(EjecucionPIIP[AvanceEjecutado]<>0),"")))),1,"")} | E10: {=IF(ISNUMBER(VALUE(_xlfn.UNIQUE(_xlfn._xlws.FILTER(CUIPO_datos_abiertos[COD_PROGRAMATICO_MGA],(CUIPO_datos_abiertos[COD_PROGRAMATICO_MGA]=Bono_2!B10)*(CUIPO_datos_abiertos[PERIODO]='Reporte'!$B$1)*(CUIPO_datos_abiertos[OBLIGACIONES]<>0),"")))),1,"")} -> 1 | F10: =IF(SUM(C10:E10)=3,"Aplica","") | V10: PIIP ∩ CUIPO (sin SISPT) | W10: {=SUMPRODUCT(($C$5:$C$322<>1)*($D$5:$D$322=1)*($E$5:$E$322=1))} -> 0
B11: 4599025 | C11: {=IF(ISNUMBER(VALUE(_xlfn.UNIQUE(_xlfn._xlws.FILTER(PI_SISPT_ProgramacionFisica[Cód. Prod.],PI_SISPT_ProgramacionFisica[Cód. Prod.]=Bono_2!B11,"")))),1,"")} -> 1 | D11: {=IF(ISNUMBER(VALUE(_xlfn.UNIQUE(_xlfn._xlws.FILTER(EjecucionPIIP[CodigoProducto],(EjecucionPIIP[CodigoProducto]=Bono_2!B11)*(EjecucionPIIP[Vigencia]=LEFT('Reporte'!$B$1,4))*(EjecucionPIIP[AvanceEjecutado]<>0),"")))),1,"")} | E11: {=IF(ISNUMBER(VALUE(_xlfn.UNIQUE(_xlfn._xlws.FILTER(CUIPO_datos_abiertos[COD_PROGRAMATICO_MGA],(CUIPO_datos_abiertos[COD_PROGRAMATICO_MGA]=Bono_2!B11)*(CUIPO_datos_abiertos[PERIODO]='Reporte'!$B$1)*(CUIPO_datos_abiertos[OBLIGACIONES]<>0),"")))),1,"")} -> 1 | F11: =IF(SUM(C11:E11)=3,"Aplica","") | V11: Los tres | W11: {=SUMPRODUCT(($C$5:$C$322=1)*($D$5:$D$322=1)*($E$5:$E$322=1))} -> 19
